第8章 异常

异常不仅仅是错误，还是一种正常的跳转逻辑。
 
8.1 异常

除多了个可选的 else 分支外，与其他语言并无多大差别。

```
>>> def test(n):
...     try:
...         if n % 2:
...             raise Exception("Error Message!")
...     except Exception as ex:
...         print("Exception:", ex.message)
...     else:
...         print("Else...")
...     finally:
...         print("Finally...")
...
>>> test(1)
('Exception:', 'Error Message!')
Finally...
>>> test(2)
Else...
Finally...
```

关键字 raise 抛出异常，else分支只在没有异常发生时执行。可无论如何，finally 总会被执行。

可以有多个 except 分支捕获不同类型的异常。

```
>>> def test(n):
...     try:
...         if n == 0:
...             raise NameError()
...         elif n == 1:
...             raise KeyError()
...         elif n == 2:
...             raise IndexError()
...         else:
...             raise Exception()
...     except (IndexError, KeyError) as ex:
...         print(type(ex))
...     except NameError:
...         print("Name Error")
...     except:
...         print("Exception")
...
>>> test(0)
Name Error
>>> test(1)
<type 'exceptions.KeyError'>
>>> test(2)
<type 'exceptions.IndexError'>
>>> test(3)
Exception
```

下面这种写法已经被Python3抛弃，不建议使用。

```
>>> def test():
...     try:
...         raise KeyError, "message"
...     except (IndexError, KeyError), ex:
...         print(type(ex))
...
```

支持在 except 中重新抛出异常。

```
>>> def test():
...     try:
...         raise Exception("error!")
...     except:
...         print("catch exception!")
...         raise
...
>>> test()
catch exception!
Traceback (most recent call last):
  File "<stdin>", line 1, in <module>
  File "<stdin>", line 3, in test
Exception: error!
```

如果需要，可用 sys.exc_info() 获取调用堆栈上的最后异常信息。

```
>>> import sys
>>> def test():
...     try:
...         raise KeyError("key error!")
...     except:
...         exc_type, exc_value, traceback = sys.exc_info()
...         sys.excepthook(exc_type, exc_value, traceback)
...
>>> test()
Traceback (most recent call last):
  File "<stdin>", line 3, in test
KeyError: 'key error!'
```

自定义异常通常继承自 Exception。应该用具体异常类型表示不同的错误行为，而不是 message 这样的状态值 。

除了异常，还可以显示警告信息。warnings 模块另有函数用来控制警告的具体行为。

```
>>> import warnings
>>> def test():
...     warnings.warn("hi!")
...     print("test...")
...
>>> test()
__main__:2: UserWarning: hi!
test...
```
 
8.2 断言

断言（assert）虽然简单，但远比用print输出调试好得多。

```
>>> def test(n):
...     assert(n > 0, "n must greater than 0")
...     print(n)
...
<stdin>:2: SyntaxWarning: assertion is always true, perhaps remove parentheses?
>>> def test(n):
...
KeyboardInterrupt
>>> def test2(n):
...     assert n > 0, "n must greater than 0"
...     print(n)
...
>>> test(1)
1
>>> test(0)
0
>>> test2(1)
1
>>> test2(0)
Traceback (most recent call last):
  File "<stdin>", line 1, in <module>
  File "<stdin>", line 2, in test2
AssertionError: n must greater than 0
```
很简单，当条件不符时，抛出AssertionError异常。assert受只读参数 __debug__ 控制，可以在启动时添加 "-O" 参数使其失效。

`python -O main.py`
 
8.3 上下文
 
上下文管理协议（Context Management Protocol）为代码块提供了包含初始化和清理操作的安全上下文环境。既便代码块发生异常，清理操作也会被执行。
 
* __enter__: 初始化环境，返回上下文对象。
* __exit__: 执行清理操作。返回True时，将阻止异常向外传递。
 
```
>>> class MyContext(object):
    def __init__(self, *args):
        self._data = args
    def __enter__(self):
        print("__enter__")
        return self._data
    def __exit__(self, exc_type, exc_value, traceback):
        if exc_type: print("Exceptin:", exc_value)
        print("__exit__")
        return True

    
>>> with MyContext(1, 2, 3) as data:
    print data

    
__enter__
(1, 2, 3)
__exit__
>>> with MyContext(1, 2, 3):
    raise Exception("data error!")

__enter__
('Exceptin:', Exception('data error!',))
__exit__
```
 
可以在一个with语句中使用多个上下文对象，依次按照FILO顺序调用。
 
```
>>> with MyContext("a"), MyContext("b"):
    print("exec code...")

    
__enter__
__enter__
exec code...
__exit__
__exit__
```
 
contextlib
 
标准库contextlib提供了 一个contextmanager装饰器，用来简化上下文类型开发。
 
```
>>> from contextlib import contextmanager
def closing(o):
    print("__enter__")
    yield o
    print("__exit__")
    o.close()

    
>>> with closing(open("README.md", "r")) as f:
    print f.readline()

    

Traceback (most recent call last):
  File "<pyshell#33>", line 1, in <module>
    with closing(open("README.md", "r")) as f:
IOError: [Errno 2] No such file or directory: 'README.md'
```
原理很简单，contextmanager替我们创建Context对象，并利用yield切换执行过程。
* 通过 __enter__ 调用 closing 函数(*注*：这里有处拼写错误)，将yield结果作为 __enter__ 返回值。
* yield 让出了 closing 执行权限，转而执行 with 代码块。
* 执行完毕后，__exit__ 发送消息，通知yield恢复closing后续代码。

和第5章提到的yield改进回调的做法差不多。contextmanager让我们少写了很多代码。但也有个麻烦，因为不是自己写 __exit__，所以得额外处理异常。
```
>>> from contextlib import contextmanager
>>> @contextmanager
... def closing(o):
...     try:
...         yield o
...     except:
...         pass
...     finally:
...         o.close()
...
```
contextlib已有现成的closing可用，不用费心完善上面的例子。
上下文管理协议的用途很广，比如：
* Synchronized: 为代码块提供 lock/unlock 线程同步。
* DBContext: 为代码块中的逻辑提供共享的数据库连接，并负责关闭连接。
* 等待......

提示：
如果你从没抛出过自定义异常，那么得好好想想了......
